<robot name="vehiclediffdrive">

<!--                    DEFINING MATERIALS   -->
  <material name="blue">
    <color rgba="0 0 1 1"/>
  </material>

  <material name="white">
    <color rgba="1 1 1 1"/>
  </material>
<material name="green">
    <color rgba=" 0.5 0.2 0.8 1"/>
  </material>

<!--Defining the robot-->
<!--                      BASE LINK            -->
    <link name="base_link">
         <inertial>
     <origin xyz="0 0 0.08" rpy="0 0 0"/>
     <mass value="21.6"/>
     <inertia ixx="0.306"  ixy="0"  ixz="0" iyy="0.36" iyz="0" izz="0.54" />
   </inertial>

   <visual>
     <origin xyz="0 0 0.08" rpy="0 0 0" />
     <geometry>
       <box size="0.2 0.4 0.1" />
     </geometry>
     <material name="blue">
     </material>
   </visual>

   <collision>
     <origin  xyz="0 0 0.08" rpy="0 0 0"/>
     <geometry>
       <box  size="0.2 0.4 0.1" />
     </geometry>
   </collision>
    </link>
    <gazebo reference="base_link">
    <material>Gazebo/Blue</material>
  </gazebo>

    <!--                    RIGHT FRONT WHEEL                       -->
<!--                    RIGHT FRONT WHEEL                       -->
    <link name="right_front_wheel">
    <inertial>
     <mass value="0.54"/>
     <inertia ixx="0.000702"  ixy="0"  ixz="0" iyy="0.000702" iyz="0" izz="0.001323" />
   </inertial>

   <visual>
     <geometry>
       <cylinder  radius ="0.07" length="0.03"/>
     </geometry>
     <material name="white">
     </material>
   </visual>

   <collision>
     <geometry>
      <cylinder  radius ="0.07" length="0.03"/>
     </geometry>
   </collision>
    </link>
    <gazebo reference="right_front_wheel">
    <material>Gazebo/White</material>
  </gazebo>

    <!--                    RIGHT BACK WHEEL                       -->
    <link name="right_back_wheel">
      <inertial>
     
     <mass value="0.54"/>
     <inertia ixx="0.000702"  ixy="0"  ixz="0" iyy="0.000702" iyz="0" izz="0.001323" />
   </inertial>

   <visual>
     
     <geometry>
     <cylinder  radius ="0.07" length="0.03"/>
     </geometry>
     <material name="white">
     </material>
   </visual>

   <collision>
     
     <geometry>
       <cylinder  radius ="0.07" length="0.03"/>
     </geometry>
   </collision>
    </link>
    <gazebo reference="right_back_wheel">
    <material>Gazebo/White</material>
  </gazebo>

   <!--                    CAMERA LINK                     -->
    <link name="camera_link">
     <inertial>
      <mass value="0.4"/>
     <inertia ixx="1"  ixy="0"  ixz="0" iyy="1" iyz="0" izz="1" />
   </inertial>

   <visual>
     
     <geometry>
       <box   size= "0.05 0.05 0.08"/>
     </geometry>
     <material name="green">
     </material>
   </visual>

   <collision>
     
     <geometry>
       <box   size= "0.05 0.05 0.08"/>
     </geometry>
   </collision>
    </link>

    <gazebo reference="camera_link">
    <material>Gazebo/Green</material>
  </gazebo>

    <!--                    LASER LINK                     -->
    <link name="laser_link">
     <inertial>
      <mass value="0.4"/>
     <inertia ixx="1"  ixy="0"  ixz="0" iyy="1" iyz="0" izz="1" />
   </inertial>

   <visual>
     
     <geometry>
       <box   size= "0.05 0.05 0.08"/>
     </geometry>
     <material name="green">
     </material>
   </visual>

   <collision>
     
     <geometry>
       <box   size= "0.05 0.05 0.08"/>
     </geometry>
   </collision>
    </link>
    
    <gazebo reference="laser_link">
    <material>Gazebo/Green</material>
  </gazebo>



    <!--                    LEFT FRONT WHEEL                       -->
    <link name="left_front_wheel">
      <inertial>
     
     <mass value="0.54"/>
     <inertia ixx="0.000702"  ixy="0"  ixz="0" iyy="0.000702" iyz="0" izz="0.001323" />
   </inertial>

   <visual>
     
     <geometry>
     <cylinder  radius ="0.07" length="0.03"/>
     </geometry>
     <material name="white">
     </material>
   </visual>

   <collision>
     
     <geometry>
       <cylinder  radius ="0.07" length="0.03"/>
     </geometry>
   </collision>
    </link>
    <gazebo reference="left_front_wheel">
    <material>Gazebo/White</material>
    </gazebo>
    
        <!--                    LEFT BACK WHEEL                       -->
    <link name="left_back_wheel">
    <inertial>
     
     <mass value="0.54"/>
     <inertia ixx="0.000702"  ixy="0"  ixz="0" iyy="0.000702" iyz="0" izz="0.001323" />
   </inertial>

   <visual>
     
     <geometry>
       <cylinder  radius ="0.07" length="0.03"/>
     </geometry>
     <material name="white">
     </material>
   </visual>

   <collision>
     
     <geometry>
       <cylinder  radius ="0.07" length="0.03"/>
     </geometry>
   </collision>
    </link><gazebo reference="left_back_wheel">
    <material>Gazebo/White</material>
  </gazebo>


        <!--                              JOINTS             -->
    <!--           JOINT BASE TO RIGHT FRONT WHEEL       -->

    <joint name="joint_base_to_right_front_wheel" type="continuous">
    <origin xyz="0.115 0.09 0.07" rpy="1.57079633 1.57079633 1.57079633"/>
    <axis xyz="0 0 1" rpy="0 0 0" />  
    <parent link="base_link"/>
    <child link="right_front_wheel"/>
    </joint>

        <!--           JOINT BASE TO RIGHT BACK WHEEL  -->
    <joint name="joint_base_to_right_back_wheel" type="continuous">
    <origin xyz="0.115 -0.09 0.07" rpy="1.57079633 1.57079633 1.57079633"/>
    <axis xyz="0 0 1"  rpy="0 0 0"/>  
    <parent link="base_link"/> 
    <child link="right_back_wheel"/>
    </joint>

      <!--           JOINT BASE TO LEFT FRONT WHEEL  -->

    <joint name="joint_base_to_left_front_wheel" type="continuous">
    <origin xyz="-0.115 0.09 0.07" rpy="1.57079633 1.57079633 1.57079633"/>
    <axis xyz="0 0 1" rpy="0 0 0" />  
    <parent link="base_link"/>
    <child link="left_front_wheel"/>
    </joint>

        <!--           JOINT BASE TO CAMERA    -->
    <joint name="joint_base_to_camera_link" type="fixed">
    <origin xyz="0.05 -0.14 0.165" rpy ="0 0 4.712 "/>
    <parent link="base_link"/>
    <child link="camera_link"/>
    </joint>

    <!--           JOINT BASE TO LASER    -->
    <joint name="joint_base_to_laser_link" type="fixed">
    <origin xyz="-0.04 -0.14 0.165" rpy ="0 0 4.712 "/>
    <parent link="base_link"/>
    <child link="laser_link"/>
    </joint>

      <!--           JOINT BASE TO LEFT BACK WHEEL    -->
    <joint name="joint_base_to_left_back_wheel" type="continuous">
    <origin xyz="-0.115 -0.09 0.07" rpy="1.57079633 1.57079633 1.57079633" />
    <axis xyz="0 0 1" rpy="0 0 0" />  
    <parent link="base_link"/>
    <child link="left_back_wheel"/>
    </joint>
<!--                    CAMERA  PLUGIN                 -->
      <gazebo reference="camera_link">
    <sensor type="depth" name="camera">       
      <always_on>true</always_on>
      <visualize>true</visualize>             
      <camera>
          <horizontal_fov>1.047</horizontal_fov>
          <image>
              <width>640</width>
              <height>480</height>
              <format>R8G8B8</format>
          </image>
          <depth_camera>

          </depth_camera>
          <clip>
              <near>0.1</near>
              <far>100</far>
          </clip>
      </camera>
      <plugin name="camera_controller" filename="libgazebo_ros_openni_kinect.so">
          <baseline>0.2</baseline>
          <alwaysOn>true</alwaysOn>
              <updateRate>10.0</updateRate>
              <cameraName>camera</cameraName>
              <frameName>camera_link</frameName>                   
          <imageTopicName>rgb/image_raw</imageTopicName>
          <depthImageTopicName>depth/image_raw</depthImageTopicName>
          <pointCloudTopicName>depth/points</pointCloudTopicName>
          <cameraInfoTopicName>rgb/camera_info</cameraInfoTopicName>              
          <depthImageCameraInfoTopicName>depth/camera_info</depthImageCameraInfoTopicName>            
          <pointCloudCutoff>0.4</pointCloudCutoff>                
              <hackBaseline>0.07</hackBaseline>
              <distortionK1>0.0</distortionK1>
              <distortionK2>0.0</distortionK2>
              <distortionK3>0.0</distortionK3>
              <distortionT1>0.0</distortionT1>
              <distortionT2>0.0</distortionT2>
          <CxPrime>0.0</CxPrime>
          <Cx>0.0</Cx>
          <Cy>0.0</Cy>
          <focalLength>0.0</focalLength>
          </plugin>
    </sensor>
  </gazebo>

<!--                        LASER PLUGIN                  -->
<gazebo reference="laser_link">
    <sensor type="gpu_ray" name="head_hokuyo_sensor">
      <pose>0 0 0 0 0 0</pose>
      <visualize>false</visualize>
      <update_rate>40</update_rate>
      <ray>
        <scan>
          <horizontal>
            <samples>720</samples>
            <resolution>1</resolution>
            <min_angle>-1.570796</min_angle>
            <max_angle>1.570796</max_angle>
          </horizontal>
        </scan>
        <range>
          <min>0.10</min>
          <max>30.0</max>
          <resolution>0.01</resolution>
        </range>
        <noise>
          <type>gaussian</type>
         
          <mean>0.0</mean>
          <stddev>0.01</stddev>
        </noise>
      </ray>
      <plugin name="gazebo_ros_head_hokuyo_controller" filename="libgazebo_ros_gpu_laser.so">
        <topicName>/vehiclediffdrive/laser/scan</topicName>
        <frameName>laser_link</frameName>
      </plugin>
    </sensor>
  </gazebo>



<!--                       ROS CONTROL      -->
<gazebo>
  <plugin name="skid_steer_drive_controller" filename="libgazebo_ros_skid_steer_drive.so">
    <updateRate>100.0</updateRate>
    <robotNamespace>vehiclediffdrive</robotNamespace> 
    <leftFrontJoint>joint_base_to_left_front_wheel</leftFrontJoint>
    <rightFrontJoint>joint_base_to_right_front_wheel</rightFrontJoint>
    <leftRearJoint>joint_base_to_left_back_wheel</leftRearJoint>
    <rightRearJoint>joint_base_to_right_back_wheel</rightRearJoint>
    <wheelSeparation>0.2</wheelSeparation>
    <wheelDiameter>0.14</wheelDiameter>
    <robotBaseFrame>base_link</robotBaseFrame>
    <torque>20</torque>
    <commandTopic>cmd_vel</commandTopic>
    <broadcastTF>true</broadcastTF>
  </plugin>
</gazebo>
</robot>

